[2021-10-12 19:21:51,587] ERROR WorkerSinkTask{id=DeveloperDb-sink-0} Task threw an uncaught and unrecoverable exception. Task is being killed and will not recover until manually restarted. Error: com.microsoft.sqlserver.jdbc.SQLServerException: The TCP/IP connection to the host mssql-sink, port 5019 has failed. Error: "Connection refused (Connection refused). Verify the connection properties. Make sure that an instance of SQL Server is running on the host and accepting TCP/IP connections at the port. Make sure that TCP connections to the port are not blocked by a firewall.". (org.apache.kafka.connect.runtime.WorkerSinkTask)
org.apache.kafka.connect.errors.ConnectException: com.microsoft.sqlserver.jdbc.SQLServerException: The TCP/IP connection to the host mssql-sink, port 5019 has failed. Error: "Connection refused (Connection refused). Verify the connection properties. Make sure that an instance of SQL Server is running on the host and accepting TCP/IP connections at the port. Make sure that TCP connections to the port are not blocked by a firewall.".
	at io.confluent.connect.jdbc.util.CachedConnectionProvider.getConnection(CachedConnectionProvider.java:59)
	at io.confluent.connect.jdbc.sink.JdbcDbWriter.write(JdbcDbWriter.java:64)
	at io.confluent.connect.jdbc.sink.JdbcSinkTask.put(JdbcSinkTask.java:84)
	at org.apache.kafka.connect.runtime.WorkerSinkTask.deliverMessages(WorkerSinkTask.java:581)
	at org.apache.kafka.connect.runtime.WorkerSinkTask.poll(WorkerSinkTask.java:329)
	at org.apache.kafka.connect.runtime.WorkerSinkTask.iteration(WorkerSinkTask.java:232)
	at org.apache.kafka.connect.runtime.WorkerSinkTask.execute(WorkerSinkTask.java:201)
	at org.apache.kafka.connect.runtime.WorkerTask.doRun(WorkerTask.java:182)
	at org.apache.kafka.connect.runtime.WorkerTask.run(WorkerTask.java:231)
	at java.base/java.util.concurrent.Executors$RunnableAdapter.call(Executors.java:515)
	at java.base/java.util.concurrent.FutureTask.run(FutureTask.java:264)
	at java.base/java.util.concurrent.ThreadPoolExecutor.runWorker(ThreadPoolExecutor.java:1128)
	at java.base/java.util.concurrent.ThreadPoolExecutor$Worker.run(ThreadPoolExecutor.java:628)
	at java.base/java.lang.Thread.run(Thread.java:829)
Caused by: com.microsoft.sqlserver.jdbc.SQLServerException: The TCP/IP connection to the host mssql-sink, port 5019 has failed. Error: "Connection refused (Connection refused). Verify the connection properties. Make sure that an instance of SQL Server is running on the host and accepting TCP/IP connections at the port. Make sure that TCP connections to the port are not blocked by a firewall.".
	at com.microsoft.sqlserver.jdbc.SQLServerException.makeFromDriverError(SQLServerException.java:234)
	at com.microsoft.sqlserver.jdbc.SQLServerException.ConvertConnectExceptionToSQLServerException(SQLServerException.java:285)
	at com.microsoft.sqlserver.jdbc.SocketFinder.findSocket(IOBuffer.java:2462)
	at com.microsoft.sqlserver.jdbc.TDSChannel.open(IOBuffer.java:668)
	at com.microsoft.sqlserver.jdbc.SQLServerConnection.connectHelper(SQLServerConnection.java:2695)
	at com.microsoft.sqlserver.jdbc.SQLServerConnection.login(SQLServerConnection.java:2362)
	at com.microsoft.sqlserver.jdbc.SQLServerConnection.connectInternal(SQLServerConnection.java:2213)
	at com.microsoft.sqlserver.jdbc.SQLServerConnection.connect(SQLServerConnection.java:1276)
	at com.microsoft.sqlserver.jdbc.SQLServerDriver.connect(SQLServerDriver.java:861)
	at java.sql/java.sql.DriverManager.getConnection(DriverManager.java:677)
	at java.sql/java.sql.DriverManager.getConnection(DriverManager.java:189)
	at io.confluent.connect.jdbc.dialect.GenericDatabaseDialect.getConnection(GenericDatabaseDialect.java:239)
	at io.confluent.connect.jdbc.util.CachedConnectionProvider.newConnection(CachedConnectionProvider.java:80)
	at io.confluent.connect.jdbc.util.CachedConnectionProvider.getConnection(CachedConnectionProvider.java:52)
	... 13 more
[2021-10-12 19:21:51,595] ERROR WorkerSinkTask{id=DeveloperDb-sink-0} Task threw an uncaught and unrecoverable exception. Task is being killed and will not recover until manually restarted (org.apache.kafka.connect.runtime.WorkerTask)
org.apache.kafka.connect.errors.ConnectException: Exiting WorkerSinkTask due to unrecoverable exception.
	at org.apache.kafka.connect.runtime.WorkerSinkTask.deliverMessages(WorkerSinkTask.java:609)
	at org.apache.kafka.connect.runtime.WorkerSinkTask.poll(WorkerSinkTask.java:329)
	at org.apache.kafka.connect.runtime.WorkerSinkTask.iteration(WorkerSinkTask.java:232)
	at org.apache.kafka.connect.runtime.WorkerSinkTask.execute(WorkerSinkTask.java:201)
	at org.apache.kafka.connect.runtime.WorkerTask.doRun(WorkerTask.java:182)
	at org.apache.kafka.connect.runtime.WorkerTask.run(WorkerTask.java:231)
	at java.base/java.util.concurrent.Executors$RunnableAdapter.call(Executors.java:515)
	at java.base/java.util.concurrent.FutureTask.run(FutureTask.java:264)
	at java.base/java.util.concurrent.ThreadPoolExecutor.runWorker(ThreadPoolExecutor.java:1128)
	at java.base/java.util.concurrent.ThreadPoolExecutor$Worker.run(ThreadPoolExecutor.java:628)
	at java.base/java.lang.Thread.run(Thread.java:829)
Caused by: org.apache.kafka.connect.errors.ConnectException: com.microsoft.sqlserver.jdbc.SQLServerException: The TCP/IP connection to the host mssql-sink, port 5019 has failed. Error: "Connection refused (Connection refused). Verify the connection properties. Make sure that an instance of SQL Server is running on the host and accepting TCP/IP connections at the port. Make sure that TCP connections to the port are not blocked by a firewall.".
	at io.confluent.connect.jdbc.util.CachedConnectionProvider.getConnection(CachedConnectionProvider.java:59)
	at io.confluent.connect.jdbc.sink.JdbcDbWriter.write(JdbcDbWriter.java:64)
	at io.confluent.connect.jdbc.sink.JdbcSinkTask.put(JdbcSinkTask.java:84)
	at org.apache.kafka.connect.runtime.WorkerSinkTask.deliverMessages(WorkerSinkTask.java:581)
	... 10 more
Caused by: com.microsoft.sqlserver.jdbc.SQLServerException: The TCP/IP connection to the host mssql-sink, port 5019 has failed. Error: "Connection refused (Connection refused). Verify the connection properties. Make sure that an instance of SQL Server is running on the host and accepting TCP/IP connections at the port. Make sure that TCP connections to the port are not blocked by a firewall.".
	at com.microsoft.sqlserver.jdbc.SQLServerException.makeFromDriverError(SQLServerException.java:234)
	at com.microsoft.sqlserver.jdbc.SQLServerException.ConvertConnectExceptionToSQLServerException(SQLServerException.java:285)
	at com.microsoft.sqlserver.jdbc.SocketFinder.findSocket(IOBuffer.java:2462)
	at com.microsoft.sqlserver.jdbc.TDSChannel.open(IOBuffer.java:668)
	at com.microsoft.sqlserver.jdbc.SQLServerConnection.connectHelper(SQLServerConnection.java:2695)
	at com.microsoft.sqlserver.jdbc.SQLServerConnection.login(SQLServerConnection.java:2362)
	at com.microsoft.sqlserver.jdbc.SQLServerConnection.connectInternal(SQLServerConnection.java:2213)
	at com.microsoft.sqlserver.jdbc.SQLServerConnection.connect(SQLServerConnection.java:1276)
	at com.microsoft.sqlserver.jdbc.SQLServerDriver.connect(SQLServerDriver.java:861)
	at java.sql/java.sql.DriverManager.getConnection(DriverManager.java:677)
	at java.sql/java.sql.DriverManager.getConnection(DriverManager.java:189)
	at io.confluent.connect.jdbc.dialect.GenericDatabaseDialect.getConnection(GenericDatabaseDialect.java:239)
	at io.confluent.connect.jdbc.util.CachedConnectionProvider.newConnection(CachedConnectionProvider.java:80)
	at io.confluent.connect.jdbc.util.CachedConnectionProvider.getConnection(CachedConnectionProvider.java:52)
	... 13 more
[2021-10-12 19:27:51,691] ERROR WorkerSinkTask{id=DeveloperDb-sink-0} RetriableException from SinkTask: (org.apache.kafka.connect.runtime.WorkerSinkTask)
org.apache.kafka.connect.errors.RetriableException: java.sql.SQLException: Exception chain:
com.microsoft.sqlserver.jdbc.SQLServerException: Database 'dbo' does not exist. Make sure that the name is entered correctly.

	at io.confluent.connect.jdbc.sink.JdbcSinkTask.put(JdbcSinkTask.java:108)
	at org.apache.kafka.connect.runtime.WorkerSinkTask.deliverMessages(WorkerSinkTask.java:581)
	at org.apache.kafka.connect.runtime.WorkerSinkTask.poll(WorkerSinkTask.java:329)
	at org.apache.kafka.connect.runtime.WorkerSinkTask.iteration(WorkerSinkTask.java:232)
	at org.apache.kafka.connect.runtime.WorkerSinkTask.execute(WorkerSinkTask.java:201)
	at org.apache.kafka.connect.runtime.WorkerTask.doRun(WorkerTask.java:182)
	at org.apache.kafka.connect.runtime.WorkerTask.run(WorkerTask.java:231)
	at java.base/java.util.concurrent.Executors$RunnableAdapter.call(Executors.java:515)
	at java.base/java.util.concurrent.FutureTask.run(FutureTask.java:264)
	at java.base/java.util.concurrent.ThreadPoolExecutor.runWorker(ThreadPoolExecutor.java:1128)
	at java.base/java.util.concurrent.ThreadPoolExecutor$Worker.run(ThreadPoolExecutor.java:628)
	at java.base/java.lang.Thread.run(Thread.java:829)
Caused by: java.sql.SQLException: Exception chain:
com.microsoft.sqlserver.jdbc.SQLServerException: Database 'dbo' does not exist. Make sure that the name is entered correctly.

	at io.confluent.connect.jdbc.sink.JdbcSinkTask.getAllMessagesException(JdbcSinkTask.java:150)
	at io.confluent.connect.jdbc.sink.JdbcSinkTask.put(JdbcSinkTask.java:102)
	... 11 more
[2021-10-12 19:27:54,738] ERROR WorkerSinkTask{id=DeveloperDb-sink-0} RetriableException from SinkTask: (org.apache.kafka.connect.runtime.WorkerSinkTask)
org.apache.kafka.connect.errors.RetriableException: java.sql.SQLException: Exception chain:
com.microsoft.sqlserver.jdbc.SQLServerException: Database 'dbo' does not exist. Make sure that the name is entered correctly.

	at io.confluent.connect.jdbc.sink.JdbcSinkTask.put(JdbcSinkTask.java:108)
	at org.apache.kafka.connect.runtime.WorkerSinkTask.deliverMessages(WorkerSinkTask.java:581)
	at org.apache.kafka.connect.runtime.WorkerSinkTask.poll(WorkerSinkTask.java:329)
	at org.apache.kafka.connect.runtime.WorkerSinkTask.iteration(WorkerSinkTask.java:232)
	at org.apache.kafka.connect.runtime.WorkerSinkTask.execute(WorkerSinkTask.java:201)
	at org.apache.kafka.connect.runtime.WorkerTask.doRun(WorkerTask.java:182)
	at org.apache.kafka.connect.runtime.WorkerTask.run(WorkerTask.java:231)
	at java.base/java.util.concurrent.Executors$RunnableAdapter.call(Executors.java:515)
	at java.base/java.util.concurrent.FutureTask.run(FutureTask.java:264)
	at java.base/java.util.concurrent.ThreadPoolExecutor.runWorker(ThreadPoolExecutor.java:1128)
	at java.base/java.util.concurrent.ThreadPoolExecutor$Worker.run(ThreadPoolExecutor.java:628)
	at java.base/java.lang.Thread.run(Thread.java:829)
Caused by: java.sql.SQLException: Exception chain:
com.microsoft.sqlserver.jdbc.SQLServerException: Database 'dbo' does not exist. Make sure that the name is entered correctly.

	at io.confluent.connect.jdbc.sink.JdbcSinkTask.getAllMessagesException(JdbcSinkTask.java:150)
	at io.confluent.connect.jdbc.sink.JdbcSinkTask.put(JdbcSinkTask.java:102)
	... 11 more
[2021-10-12 19:27:57,796] ERROR WorkerSinkTask{id=DeveloperDb-sink-0} RetriableException from SinkTask: (org.apache.kafka.connect.runtime.WorkerSinkTask)
org.apache.kafka.connect.errors.RetriableException: java.sql.SQLException: Exception chain:
com.microsoft.sqlserver.jdbc.SQLServerException: Database 'dbo' does not exist. Make sure that the name is entered correctly.

	at io.confluent.connect.jdbc.sink.JdbcSinkTask.put(JdbcSinkTask.java:108)
	at org.apache.kafka.connect.runtime.WorkerSinkTask.deliverMessages(WorkerSinkTask.java:581)
	at org.apache.kafka.connect.runtime.WorkerSinkTask.poll(WorkerSinkTask.java:329)
	at org.apache.kafka.connect.runtime.WorkerSinkTask.iteration(WorkerSinkTask.java:232)
	at org.apache.kafka.connect.runtime.WorkerSinkTask.execute(WorkerSinkTask.java:201)
	at org.apache.kafka.connect.runtime.WorkerTask.doRun(WorkerTask.java:182)
	at org.apache.kafka.connect.runtime.WorkerTask.run(WorkerTask.java:231)
	at java.base/java.util.concurrent.Executors$RunnableAdapter.call(Executors.java:515)
	at java.base/java.util.concurrent.FutureTask.run(FutureTask.java:264)
	at java.base/java.util.concurrent.ThreadPoolExecutor.runWorker(ThreadPoolExecutor.java:1128)
	at java.base/java.util.concurrent.ThreadPoolExecutor$Worker.run(ThreadPoolExecutor.java:628)
	at java.base/java.lang.Thread.run(Thread.java:829)
Caused by: java.sql.SQLException: Exception chain:
com.microsoft.sqlserver.jdbc.SQLServerException: Database 'dbo' does not exist. Make sure that the name is entered correctly.

	at io.confluent.connect.jdbc.sink.JdbcSinkTask.getAllMessagesException(JdbcSinkTask.java:150)
	at io.confluent.connect.jdbc.sink.JdbcSinkTask.put(JdbcSinkTask.java:102)
	... 11 more
[2021-10-12 19:28:00,825] ERROR WorkerSinkTask{id=DeveloperDb-sink-0} RetriableException from SinkTask: (org.apache.kafka.connect.runtime.WorkerSinkTask)
org.apache.kafka.connect.errors.RetriableException: java.sql.SQLException: Exception chain:
com.microsoft.sqlserver.jdbc.SQLServerException: Database 'dbo' does not exist. Make sure that the name is entered correctly.

	at io.confluent.connect.jdbc.sink.JdbcSinkTask.put(JdbcSinkTask.java:108)
	at org.apache.kafka.connect.runtime.WorkerSinkTask.deliverMessages(WorkerSinkTask.java:581)
	at org.apache.kafka.connect.runtime.WorkerSinkTask.poll(WorkerSinkTask.java:329)
	at org.apache.kafka.connect.runtime.WorkerSinkTask.iteration(WorkerSinkTask.java:232)
	at org.apache.kafka.connect.runtime.WorkerSinkTask.execute(WorkerSinkTask.java:201)
	at org.apache.kafka.connect.runtime.WorkerTask.doRun(WorkerTask.java:182)
	at org.apache.kafka.connect.runtime.WorkerTask.run(WorkerTask.java:231)
	at java.base/java.util.concurrent.Executors$RunnableAdapter.call(Executors.java:515)
	at java.base/java.util.concurrent.FutureTask.run(FutureTask.java:264)
	at java.base/java.util.concurrent.ThreadPoolExecutor.runWorker(ThreadPoolExecutor.java:1128)
	at java.base/java.util.concurrent.ThreadPoolExecutor$Worker.run(ThreadPoolExecutor.java:628)
	at java.base/java.lang.Thread.run(Thread.java:829)
Caused by: java.sql.SQLException: Exception chain:
com.microsoft.sqlserver.jdbc.SQLServerException: Database 'dbo' does not exist. Make sure that the name is entered correctly.

	at io.confluent.connect.jdbc.sink.JdbcSinkTask.getAllMessagesException(JdbcSinkTask.java:150)
	at io.confluent.connect.jdbc.sink.JdbcSinkTask.put(JdbcSinkTask.java:102)
	... 11 more
[2021-10-12 19:28:03,852] ERROR WorkerSinkTask{id=DeveloperDb-sink-0} RetriableException from SinkTask: (org.apache.kafka.connect.runtime.WorkerSinkTask)
org.apache.kafka.connect.errors.RetriableException: java.sql.SQLException: Exception chain:
com.microsoft.sqlserver.jdbc.SQLServerException: Database 'dbo' does not exist. Make sure that the name is entered correctly.

	at io.confluent.connect.jdbc.sink.JdbcSinkTask.put(JdbcSinkTask.java:108)
	at org.apache.kafka.connect.runtime.WorkerSinkTask.deliverMessages(WorkerSinkTask.java:581)
	at org.apache.kafka.connect.runtime.WorkerSinkTask.poll(WorkerSinkTask.java:329)
	at org.apache.kafka.connect.runtime.WorkerSinkTask.iteration(WorkerSinkTask.java:232)
	at org.apache.kafka.connect.runtime.WorkerSinkTask.execute(WorkerSinkTask.java:201)
	at org.apache.kafka.connect.runtime.WorkerTask.doRun(WorkerTask.java:182)
	at org.apache.kafka.connect.runtime.WorkerTask.run(WorkerTask.java:231)
	at java.base/java.util.concurrent.Executors$RunnableAdapter.call(Executors.java:515)
	at java.base/java.util.concurrent.FutureTask.run(FutureTask.java:264)
	at java.base/java.util.concurrent.ThreadPoolExecutor.runWorker(ThreadPoolExecutor.java:1128)
	at java.base/java.util.concurrent.ThreadPoolExecutor$Worker.run(ThreadPoolExecutor.java:628)
	at java.base/java.lang.Thread.run(Thread.java:829)
Caused by: java.sql.SQLException: Exception chain:
com.microsoft.sqlserver.jdbc.SQLServerException: Database 'dbo' does not exist. Make sure that the name is entered correctly.

	at io.confluent.connect.jdbc.sink.JdbcSinkTask.getAllMessagesException(JdbcSinkTask.java:150)
	at io.confluent.connect.jdbc.sink.JdbcSinkTask.put(JdbcSinkTask.java:102)
	... 11 more
[2021-10-12 19:28:06,881] ERROR WorkerSinkTask{id=DeveloperDb-sink-0} RetriableException from SinkTask: (org.apache.kafka.connect.runtime.WorkerSinkTask)
org.apache.kafka.connect.errors.RetriableException: java.sql.SQLException: Exception chain:
com.microsoft.sqlserver.jdbc.SQLServerException: Database 'dbo' does not exist. Make sure that the name is entered correctly.

	at io.confluent.connect.jdbc.sink.JdbcSinkTask.put(JdbcSinkTask.java:108)
	at org.apache.kafka.connect.runtime.WorkerSinkTask.deliverMessages(WorkerSinkTask.java:581)
	at org.apache.kafka.connect.runtime.WorkerSinkTask.poll(WorkerSinkTask.java:329)
	at org.apache.kafka.connect.runtime.WorkerSinkTask.iteration(WorkerSinkTask.java:232)
	at org.apache.kafka.connect.runtime.WorkerSinkTask.execute(WorkerSinkTask.java:201)
	at org.apache.kafka.connect.runtime.WorkerTask.doRun(WorkerTask.java:182)
	at org.apache.kafka.connect.runtime.WorkerTask.run(WorkerTask.java:231)
	at java.base/java.util.concurrent.Executors$RunnableAdapter.call(Executors.java:515)
	at java.base/java.util.concurrent.FutureTask.run(FutureTask.java:264)
	at java.base/java.util.concurrent.ThreadPoolExecutor.runWorker(ThreadPoolExecutor.java:1128)
	at java.base/java.util.concurrent.ThreadPoolExecutor$Worker.run(ThreadPoolExecutor.java:628)
	at java.base/java.lang.Thread.run(Thread.java:829)
Caused by: java.sql.SQLException: Exception chain:
com.microsoft.sqlserver.jdbc.SQLServerException: Database 'dbo' does not exist. Make sure that the name is entered correctly.

	at io.confluent.connect.jdbc.sink.JdbcSinkTask.getAllMessagesException(JdbcSinkTask.java:150)
	at io.confluent.connect.jdbc.sink.JdbcSinkTask.put(JdbcSinkTask.java:102)
	... 11 more
[2021-10-12 19:28:09,907] ERROR WorkerSinkTask{id=DeveloperDb-sink-0} RetriableException from SinkTask: (org.apache.kafka.connect.runtime.WorkerSinkTask)
org.apache.kafka.connect.errors.RetriableException: java.sql.SQLException: Exception chain:
com.microsoft.sqlserver.jdbc.SQLServerException: Database 'dbo' does not exist. Make sure that the name is entered correctly.

	at io.confluent.connect.jdbc.sink.JdbcSinkTask.put(JdbcSinkTask.java:108)
	at org.apache.kafka.connect.runtime.WorkerSinkTask.deliverMessages(WorkerSinkTask.java:581)
	at org.apache.kafka.connect.runtime.WorkerSinkTask.poll(WorkerSinkTask.java:329)
	at org.apache.kafka.connect.runtime.WorkerSinkTask.iteration(WorkerSinkTask.java:232)
	at org.apache.kafka.connect.runtime.WorkerSinkTask.execute(WorkerSinkTask.java:201)
	at org.apache.kafka.connect.runtime.WorkerTask.doRun(WorkerTask.java:182)
	at org.apache.kafka.connect.runtime.WorkerTask.run(WorkerTask.java:231)
	at java.base/java.util.concurrent.Executors$RunnableAdapter.call(Executors.java:515)
	at java.base/java.util.concurrent.FutureTask.run(FutureTask.java:264)
	at java.base/java.util.concurrent.ThreadPoolExecutor.runWorker(ThreadPoolExecutor.java:1128)
	at java.base/java.util.concurrent.ThreadPoolExecutor$Worker.run(ThreadPoolExecutor.java:628)
	at java.base/java.lang.Thread.run(Thread.java:829)
Caused by: java.sql.SQLException: Exception chain:
com.microsoft.sqlserver.jdbc.SQLServerException: Database 'dbo' does not exist. Make sure that the name is entered correctly.

	at io.confluent.connect.jdbc.sink.JdbcSinkTask.getAllMessagesException(JdbcSinkTask.java:150)
	at io.confluent.connect.jdbc.sink.JdbcSinkTask.put(JdbcSinkTask.java:102)
	... 11 more
[2021-10-12 19:28:12,943] ERROR WorkerSinkTask{id=DeveloperDb-sink-0} RetriableException from SinkTask: (org.apache.kafka.connect.runtime.WorkerSinkTask)
org.apache.kafka.connect.errors.RetriableException: java.sql.SQLException: Exception chain:
com.microsoft.sqlserver.jdbc.SQLServerException: Database 'dbo' does not exist. Make sure that the name is entered correctly.

	at io.confluent.connect.jdbc.sink.JdbcSinkTask.put(JdbcSinkTask.java:108)
	at org.apache.kafka.connect.runtime.WorkerSinkTask.deliverMessages(WorkerSinkTask.java:581)
	at org.apache.kafka.connect.runtime.WorkerSinkTask.poll(WorkerSinkTask.java:329)
	at org.apache.kafka.connect.runtime.WorkerSinkTask.iteration(WorkerSinkTask.java:232)
	at org.apache.kafka.connect.runtime.WorkerSinkTask.execute(WorkerSinkTask.java:201)
	at org.apache.kafka.connect.runtime.WorkerTask.doRun(WorkerTask.java:182)
	at org.apache.kafka.connect.runtime.WorkerTask.run(WorkerTask.java:231)
	at java.base/java.util.concurrent.Executors$RunnableAdapter.call(Executors.java:515)
	at java.base/java.util.concurrent.FutureTask.run(FutureTask.java:264)
	at java.base/java.util.concurrent.ThreadPoolExecutor.runWorker(ThreadPoolExecutor.java:1128)
	at java.base/java.util.concurrent.ThreadPoolExecutor$Worker.run(ThreadPoolExecutor.java:628)
	at java.base/java.lang.Thread.run(Thread.java:829)
Caused by: java.sql.SQLException: Exception chain:
com.microsoft.sqlserver.jdbc.SQLServerException: Database 'dbo' does not exist. Make sure that the name is entered correctly.

	at io.confluent.connect.jdbc.sink.JdbcSinkTask.getAllMessagesException(JdbcSinkTask.java:150)
	at io.confluent.connect.jdbc.sink.JdbcSinkTask.put(JdbcSinkTask.java:102)
	... 11 more
[2021-10-12 19:28:16,005] ERROR WorkerSinkTask{id=DeveloperDb-sink-0} RetriableException from SinkTask: (org.apache.kafka.connect.runtime.WorkerSinkTask)
org.apache.kafka.connect.errors.RetriableException: java.sql.SQLException: Exception chain:
com.microsoft.sqlserver.jdbc.SQLServerException: Database 'dbo' does not exist. Make sure that the name is entered correctly.

	at io.confluent.connect.jdbc.sink.JdbcSinkTask.put(JdbcSinkTask.java:108)
	at org.apache.kafka.connect.runtime.WorkerSinkTask.deliverMessages(WorkerSinkTask.java:581)
	at org.apache.kafka.connect.runtime.WorkerSinkTask.poll(WorkerSinkTask.java:329)
	at org.apache.kafka.connect.runtime.WorkerSinkTask.iteration(WorkerSinkTask.java:232)
	at org.apache.kafka.connect.runtime.WorkerSinkTask.execute(WorkerSinkTask.java:201)
	at org.apache.kafka.connect.runtime.WorkerTask.doRun(WorkerTask.java:182)
	at org.apache.kafka.connect.runtime.WorkerTask.run(WorkerTask.java:231)
	at java.base/java.util.concurrent.Executors$RunnableAdapter.call(Executors.java:515)
	at java.base/java.util.concurrent.FutureTask.run(FutureTask.java:264)
	at java.base/java.util.concurrent.ThreadPoolExecutor.runWorker(ThreadPoolExecutor.java:1128)
	at java.base/java.util.concurrent.ThreadPoolExecutor$Worker.run(ThreadPoolExecutor.java:628)
	at java.base/java.lang.Thread.run(Thread.java:829)
Caused by: java.sql.SQLException: Exception chain:
com.microsoft.sqlserver.jdbc.SQLServerException: Database 'dbo' does not exist. Make sure that the name is entered correctly.

	at io.confluent.connect.jdbc.sink.JdbcSinkTask.getAllMessagesException(JdbcSinkTask.java:150)
	at io.confluent.connect.jdbc.sink.JdbcSinkTask.put(JdbcSinkTask.java:102)
	... 11 more
[2021-10-12 19:28:19,030] ERROR WorkerSinkTask{id=DeveloperDb-sink-0} RetriableException from SinkTask: (org.apache.kafka.connect.runtime.WorkerSinkTask)
org.apache.kafka.connect.errors.RetriableException: java.sql.SQLException: Exception chain:
com.microsoft.sqlserver.jdbc.SQLServerException: Database 'dbo' does not exist. Make sure that the name is entered correctly.

	at io.confluent.connect.jdbc.sink.JdbcSinkTask.put(JdbcSinkTask.java:108)
	at org.apache.kafka.connect.runtime.WorkerSinkTask.deliverMessages(WorkerSinkTask.java:581)
	at org.apache.kafka.connect.runtime.WorkerSinkTask.poll(WorkerSinkTask.java:329)
	at org.apache.kafka.connect.runtime.WorkerSinkTask.iteration(WorkerSinkTask.java:232)
	at org.apache.kafka.connect.runtime.WorkerSinkTask.execute(WorkerSinkTask.java:201)
	at org.apache.kafka.connect.runtime.WorkerTask.doRun(WorkerTask.java:182)
	at org.apache.kafka.connect.runtime.WorkerTask.run(WorkerTask.java:231)
	at java.base/java.util.concurrent.Executors$RunnableAdapter.call(Executors.java:515)
	at java.base/java.util.concurrent.FutureTask.run(FutureTask.java:264)
	at java.base/java.util.concurrent.ThreadPoolExecutor.runWorker(ThreadPoolExecutor.java:1128)
	at java.base/java.util.concurrent.ThreadPoolExecutor$Worker.run(ThreadPoolExecutor.java:628)
	at java.base/java.lang.Thread.run(Thread.java:829)
Caused by: java.sql.SQLException: Exception chain:
com.microsoft.sqlserver.jdbc.SQLServerException: Database 'dbo' does not exist. Make sure that the name is entered correctly.

	at io.confluent.connect.jdbc.sink.JdbcSinkTask.getAllMessagesException(JdbcSinkTask.java:150)
	at io.confluent.connect.jdbc.sink.JdbcSinkTask.put(JdbcSinkTask.java:102)
	... 11 more
[2021-10-12 19:28:22,056] ERROR Failing task after exhausting retries; encountered 1 exceptions on last write attempt. For complete details on each exception, please enable DEBUG logging. (io.confluent.connect.jdbc.sink.JdbcSinkTask)
[2021-10-12 19:28:22,058] ERROR WorkerSinkTask{id=DeveloperDb-sink-0} Task threw an uncaught and unrecoverable exception. Task is being killed and will not recover until manually restarted. Error: java.sql.SQLException: Exception chain:
com.microsoft.sqlserver.jdbc.SQLServerException: Database 'dbo' does not exist. Make sure that the name is entered correctly.
 (org.apache.kafka.connect.runtime.WorkerSinkTask)
org.apache.kafka.connect.errors.ConnectException: java.sql.SQLException: Exception chain:
com.microsoft.sqlserver.jdbc.SQLServerException: Database 'dbo' does not exist. Make sure that the name is entered correctly.

	at io.confluent.connect.jdbc.sink.JdbcSinkTask.put(JdbcSinkTask.java:122)
	at org.apache.kafka.connect.runtime.WorkerSinkTask.deliverMessages(WorkerSinkTask.java:581)
	at org.apache.kafka.connect.runtime.WorkerSinkTask.poll(WorkerSinkTask.java:329)
	at org.apache.kafka.connect.runtime.WorkerSinkTask.iteration(WorkerSinkTask.java:232)
	at org.apache.kafka.connect.runtime.WorkerSinkTask.execute(WorkerSinkTask.java:201)
	at org.apache.kafka.connect.runtime.WorkerTask.doRun(WorkerTask.java:182)
	at org.apache.kafka.connect.runtime.WorkerTask.run(WorkerTask.java:231)
	at java.base/java.util.concurrent.Executors$RunnableAdapter.call(Executors.java:515)
	at java.base/java.util.concurrent.FutureTask.run(FutureTask.java:264)
	at java.base/java.util.concurrent.ThreadPoolExecutor.runWorker(ThreadPoolExecutor.java:1128)
	at java.base/java.util.concurrent.ThreadPoolExecutor$Worker.run(ThreadPoolExecutor.java:628)
	at java.base/java.lang.Thread.run(Thread.java:829)
Caused by: java.sql.SQLException: Exception chain:
com.microsoft.sqlserver.jdbc.SQLServerException: Database 'dbo' does not exist. Make sure that the name is entered correctly.

	at io.confluent.connect.jdbc.sink.JdbcSinkTask.getAllMessagesException(JdbcSinkTask.java:150)
	at io.confluent.connect.jdbc.sink.JdbcSinkTask.put(JdbcSinkTask.java:102)
	... 11 more
[2021-10-12 19:28:22,059] ERROR WorkerSinkTask{id=DeveloperDb-sink-0} Task threw an uncaught and unrecoverable exception. Task is being killed and will not recover until manually restarted (org.apache.kafka.connect.runtime.WorkerTask)
org.apache.kafka.connect.errors.ConnectException: Exiting WorkerSinkTask due to unrecoverable exception.
	at org.apache.kafka.connect.runtime.WorkerSinkTask.deliverMessages(WorkerSinkTask.java:609)
	at org.apache.kafka.connect.runtime.WorkerSinkTask.poll(WorkerSinkTask.java:329)
	at org.apache.kafka.connect.runtime.WorkerSinkTask.iteration(WorkerSinkTask.java:232)
	at org.apache.kafka.connect.runtime.WorkerSinkTask.execute(WorkerSinkTask.java:201)
	at org.apache.kafka.connect.runtime.WorkerTask.doRun(WorkerTask.java:182)
	at org.apache.kafka.connect.runtime.WorkerTask.run(WorkerTask.java:231)
	at java.base/java.util.concurrent.Executors$RunnableAdapter.call(Executors.java:515)
	at java.base/java.util.concurrent.FutureTask.run(FutureTask.java:264)
	at java.base/java.util.concurrent.ThreadPoolExecutor.runWorker(ThreadPoolExecutor.java:1128)
	at java.base/java.util.concurrent.ThreadPoolExecutor$Worker.run(ThreadPoolExecutor.java:628)
	at java.base/java.lang.Thread.run(Thread.java:829)
Caused by: org.apache.kafka.connect.errors.ConnectException: java.sql.SQLException: Exception chain:
com.microsoft.sqlserver.jdbc.SQLServerException: Database 'dbo' does not exist. Make sure that the name is entered correctly.

	at io.confluent.connect.jdbc.sink.JdbcSinkTask.put(JdbcSinkTask.java:122)
	at org.apache.kafka.connect.runtime.WorkerSinkTask.deliverMessages(WorkerSinkTask.java:581)
	... 10 more
Caused by: java.sql.SQLException: Exception chain:
com.microsoft.sqlserver.jdbc.SQLServerException: Database 'dbo' does not exist. Make sure that the name is entered correctly.

	at io.confluent.connect.jdbc.sink.JdbcSinkTask.getAllMessagesException(JdbcSinkTask.java:150)
	at io.confluent.connect.jdbc.sink.JdbcSinkTask.put(JdbcSinkTask.java:102)
	... 11 more
